....................................127.0.0.1
127.0.0.1
127.0.0.1
127.0.0.1
127.0.0.1
127.0.0.1
127.0.0.1
127.0.0.1
127.0.0.1
127.0.0.1
Exception in thread Thread-31:
Traceback (most recent call last):
  File "/usr/lib/python2.7/threading.py", line 810, in __bootstrap_inner
    self.run()
  File "/usr/lib/python2.7/threading.py", line 763, in run
    self.__target(*self.__args, **self.__kwargs)
  File "/usr/lib/python2.7/SocketServer.py", line 236, in serve_forever
    poll_interval)
  File "/usr/lib/python2.7/SocketServer.py", line 155, in _eintr_retry
    return func(*args)
error: (9, 'Bad file number')

.127.0.0.1
127.0.0.1
127.0.0.1
127.0.0.1
127.0.0.1
127.0.0.1
127.0.0.1
127.0.0.1
127.0.0.1
127.0.0.1
Exception in thread Thread-32:
Traceback (most recent call last):
  File "/usr/lib/python2.7/threading.py", line 810, in __bootstrap_inner
    self.run()
  File "/usr/lib/python2.7/threading.py", line 763, in run
    self.__target(*self.__args, **self.__kwargs)
  File "/usr/lib/python2.7/SocketServer.py", line 236, in serve_forever
    poll_interval)
  File "/usr/lib/python2.7/SocketServer.py", line 155, in _eintr_retry
    return func(*args)
error: (9, 'Bad file number')

..............
----------------------------------------------------------------------
Ran 51 tests in

OK
